Workbook

Sheet prestamos_biblioteca_publica
A1: fecha_prestamo | B1: categoria_libro | C1: idioma | D1: duracion_prestamo_dias | E1: devuelto_a_tiempo | F1: franja_horaria | G1: mes | H1: dia_semana
A2: 45662 | B2: ficcion | C2: español | D2: 14 | E2: si | F2: tarde | G2: enero | H2: domingo
A3: 45664 | B3: ensayo | C3: español | D3: 21 | E3: si | F3: mañana | G3: enero | H3: martes
A4: 45665 | B4: infantil | C4: español | D4: 10 | E4: si | F4: tarde | G4: enero | H4: miércoles
A5: 45667 | B5: comic | C5: español | D5: 7 | E5: si | F5: tarde | G5: enero | H5: viernes
A6: 45669 | B6: ficcion | C6: inglés | D6: 15 | E6: no | F6: mañana | G6: enero | H6: domingo
A7: 45671 | B7: ficcion | C7: español | D7: 14 | E7: si | F7: tarde | G7: enero | H7: martes
A8: 45672 | B8: novela_grafica | C8: español | D8: 18 | E8: si | F8: mañana | G8: enero | H8: miércoles
A9: 45674 | B9: ensayo | C9: catalán | D9: 25 | E9: si | F9: tarde | G9: enero | H9: viernes
A10: 45676 | B10: infantil | C10: español | D10: 8 | E10: si | F10: tarde | G10: enero | H10: domingo
A11: 45678 | B11: ficcion | C11: español | D11: 14 | E11: si | F11: mañana | G11: enero | H11: martes
A12: 45679 | B12: poesia | C12: español | D12: 30 | E12: no | F12: tarde | G12: enero | H12: miércoles
A13: 45681 | B13: ficcion | C13: inglés | D13: 14 | E13: si | F13: tarde | G13: enero | H13: viernes
... A262: 45808 | B262: infantil | C262: español | D262: 10 | E262: si | F262: tarde | G262: mayo | H262: sábado

Sheet Copia de Tabla
A1: fecha_prestamo | B1: categoria_libro | C1: idioma | D1: duracion_prestamo_dias | E1: devuelto_a_tiempo | F1: franja_horaria | G1: mes | H1: mes_numerado | I1: dia_semana | J1: dia_semana_numerado
A2: 45660 | B2: ensayo | C2: español | D2: 22 | E2: si | F2: tarde | G2: enero | H2: =IFS(G2="enero","01_enero",G2="febrero","02_febrero",G2="marzo","03_marzo",G2="abril","04_abril",G2="mayo","05_mayo",G2="junio","06_junio",G2="julio","07_julio",G2="agosto","08_agosto",G2="septiembre","09_septiembre",G2="octubre","10_octubre",G2="noviembre","11_noviembre",G2="diciembre","12_diciembre") -> 01_enero | I2: viernes | J2: =IFS(I2="lunes","1_lunes",I2="martes","2_martes",I2="miércoles","3_miércoles",I2="jueves","4_jueves",I2="viernes","5_viernes",I2="sábado","6_sábado",I2="domingo","7_domingo") -> 5_viernes
A3: 45662 | B3: ficcion | C3: español | D3: 14 | E3: si | F3: tarde | G3: enero | H3: =IFS(G3="enero","01_enero",G3="febrero","02_febrero",G3="marzo","03_marzo",G3="abril","04_abril",G3="mayo","05_mayo",G3="junio","06_junio",G3="julio","07_julio",G3="agosto","08_agosto",G3="septiembre","09_septiembre",G3="octubre","10_octubre",G3="noviembre","11_noviembre",G3="diciembre","12_diciembre") -> 01_enero | I3: domingo | J3: =IFS(I3="lunes","1_lunes",I3="martes","2_martes",I3="miércoles","3_miércoles",I3="jueves","4_jueves",I3="viernes","5_viernes",I3="sábado","6_sábado",I3="domingo","7_domingo") -> 7_domingo
A4: 45663 | B4: ficcion | C4: español | D4: 14 | E4: si | F4: tarde | G4: enero | H4: =IFS(G4="enero","01_enero",G4="febrero","02_febrero",G4="marzo","03_marzo",G4="abril","04_abril",G4="mayo","05_mayo",G4="junio","06_junio",G4="julio","07_julio",G4="agosto","08_agosto",G4="septiembre","09_septiembre",G4="octubre","10_octubre",G4="noviembre","11_noviembre",G4="diciembre","12_diciembre") -> 01_enero | I4: lunes | J4: =IFS(I4="lunes","1_lunes",I4="martes","2_martes",I4="miércoles","3_miércoles",I4="jueves","4_jueves",I4="viernes","5_viernes",I4="sábado","6_sábado",I4="domingo","7_domingo") -> 1_lunes | L4: Categorias | M4: Prestamos | N4: %Préstamos_categoría | O4: Días por categoría:
A5: 45664 | B5: ensayo | C5: español | D5: 21 | E5: si | F5: mañana | G5: enero | H5: =IFS(G5="enero","01_enero",G5="febrero","02_febrero",G5="marzo","03_marzo",G5="abril","04_abril",G5="mayo","05_mayo",G5="junio","06_junio",G5="julio","07_julio",G5="agosto","08_agosto",G5="septiembre","09_septiembre",G5="octubre","10_octubre",G5="noviembre","11_noviembre",G5="diciembre","12_diciembre") -> 01_enero | I5: martes | J5: =IFS(I5="lunes","1_lunes",I5="martes","2_martes",I5="miércoles","3_miércoles",I5="jueves","4_jueves",I5="viernes","5_viernes",I5="sábado","6_sábado",I5="domingo","7_domingo") -> 2_martes | L5: Ficción | M5: =COUNTIF(B$2:B$350, "ficcion") -> 103 | N5: =(COUNTIF(B$2:B4350, "ficcion")/COUNTA(B$2:B$350)*100) -> 39.463602 | O5: =AVERAGEIF($B$2:$B$350,$B$3,$D$2:$D$350) -> 14.873786
A6: 45665 | B6: infantil | C6: español | D6: 10 | E6: si | F6: tarde | G6: enero | H6: =IFS(G6="enero","01_enero",G6="febrero","02_febrero",G6="marzo","03_marzo",G6="abril","04_abril",G6="mayo","05_mayo",G6="junio","06_junio",G6="julio","07_julio",G6="agosto","08_agosto",G6="septiembre","09_septiembre",G6="octubre","10_octubre",G6="noviembre","11_noviembre",G6="diciembre","12_diciembre") -> 01_enero | I6: miércoles | J6: =IFS(I6="lunes","1_lunes",I6="martes","2_martes",I6="miércoles","3_miércoles",I6="jueves","4_jueves",I6="viernes","5_viernes",I6="sábado","6_sábado",I6="domingo","7_domingo") -> 3_miércoles | L6: Ensayo | M6: =COUNTIF(B$2:B$350, "ensayo") -> 34 | N6: =(COUNTIF(B$2:B4351, "ensayo")/COUNTA(B$2:B$350)*100) -> 13.02682 | O6: =AVERAGEIF($B$2:C$350,$B$5,$D$2:$D$350) -> 22.558824
A7: 45666 | B7: comic | C7: español | D7: 7 | E7: si | F7: mañana | G7: enero | H7: =IFS(G7="enero","01_enero",G7="febrero","02_febrero",G7="marzo","03_marzo",G7="abril","04_abril",G7="mayo","05_mayo",G7="junio","06_junio",G7="julio","07_julio",G7="agosto","08_agosto",G7="septiembre","09_septiembre",G7="octubre","10_octubre",G7="noviembre","11_noviembre",G7="diciembre","12_diciembre") -> 01_enero | I7: jueves | J7: =IFS(I7="lunes","1_lunes",I7="martes","2_martes",I7="miércoles","3_miércoles",I7="jueves","4_jueves",I7="viernes","5_viernes",I7="sábado","6_sábado",I7="domingo","7_domingo") -> 4_jueves | L7: Infantil | M7: =COUNTIF(B$2:B$350, "infantil") -> 55 | N7: =(COUNTIF(B$2:B4352, "infantil")/COUNTA(B$2:B$350)*100) -> 21.072797 | O7: =AVERAGEIF($B$2:$B$350,$B$9,$D$2:$D$350) -> 10.454545
A8: 45667 | B8: comic | C8: español | D8: 7 | E8: si | F8: tarde | G8: enero | H8: =IFS(G8="enero","01_enero",G8="febrero","02_febrero",G8="marzo","03_marzo",G8="abril","04_abril",G8="mayo","05_mayo",G8="junio","06_junio",G8="julio","07_julio",G8="agosto","08_agosto",G8="septiembre","09_septiembre",G8="octubre","10_octubre",G8="noviembre","11_noviembre",G8="diciembre","12_diciembre") -> 01_enero | I8: viernes | J8: =IFS(I8="lunes","1_lunes",I8="martes","2_martes",I8="miércoles","3_miércoles",I8="jueves","4_jueves",I8="viernes","5_viernes",I8="sábado","6_sábado",I8="domingo","7_domingo") -> 5_viernes | L8: Cómic | M8: =COUNTIF(B$2:B$350, "comic") -> 35 | N8: =(COUNTIF(B$2:B4353, "comic")/COUNTA(B$2:B$350)*100) -> 13.409962 | O8: =AVERAGEIF($B$2:$B$350,$B$7,$D$2:$D$350) -> 7
A9: 45668 | B9: infantil | C9: español | D9: 9 | E9: si | F9: tarde | G9: enero | H9: =IFS(G9="enero","01_enero",G9="febrero","02_febrero",G9="marzo","03_marzo",G9="abril","04_abril",G9="mayo","05_mayo",G9="junio","06_junio",G9="julio","07_julio",G9="agosto","08_agosto",G9="septiembre","09_septiembre",G9="octubre","10_octubre",G9="noviembre","11_noviembre",G9="diciembre","12_diciembre") -> 01_enero | I9: sábado | J9: =IFS(I9="lunes","1_lunes",I9="martes","2_martes",I9="miércoles","3_miércoles",I9="jueves","4_jueves",I9="viernes","5_viernes",I9="sábado","6_sábado",I9="domingo","7_domingo") -> 6_sábado | L9: Poesía | M9: =COUNTIF(B$2:B$350, "poesia") -> 3 | N9: =(COUNTIF(B$2:B4354, "poesia")/COUNTA(B$2:B$350)*100) -> 1.1494253 | O9: =AVERAGEIF($B$2:$B$350,$B$71,$D$2:$D$350) -> 31
A10: 45669 | B10: ficcion | C10: inglés | D10: 15 | E10: no | F10: mañana | G10: enero | H10: =IFS(G10="enero","01_enero",G10="febrero","02_febrero",G10="marzo","03_marzo",G10="abril","04_abril",G10="mayo","05_mayo",G10="junio","06_junio",G10="julio","07_julio",G10="agosto","08_agosto",G10="septiembre","09_septiembre",G10="octubre","10_octubre",G10="noviembre","11_noviembre",G10="diciembre","12_diciembre") -> 01_enero | I10: domingo | J10: =IFS(I10="lunes","1_lunes",I10="martes","2_martes",I10="miércoles","3_miércoles",I10="jueves","4_jueves",I10="viernes","5_viernes",I10="sábado","6_sábado",I10="domingo","7_domingo") -> 7_domingo | L10: Novela gráfica | M10: =COUNTIF(B$2:B$350, "novela_grafica") -> 17 | N10: =(COUNTIF(B$2:B4355, "novela_grafica")/COUNTA(B$2:B$350)*100) -> 6.51341 | O10: =AVERAGEIF($B$2:$B$350,$B$8,$D$2:$D$350) -> 7
A11: 45670 | B11: ficcion | C11: inglés | D11: 14 | E11: si | F11: tarde | G11: enero | H11: =IFS(G11="enero","01_enero",G11="febrero","02_febrero",G11="marzo","03_marzo",G11="abril","04_abril",G11="mayo","05_mayo",G11="junio","06_junio",G11="julio","07_julio",G11="agosto","08_agosto",G11="septiembre","09_septiembre",G11="octubre","10_octubre",G11="noviembre","11_noviembre",G11="diciembre","12_diciembre") -> 01_enero | I11: lunes | J11: =IFS(I11="lunes","1_lunes",I11="martes","2_martes",I11="miércoles","3_miércoles",I11="jueves","4_jueves",I11="viernes","5_viernes",I11="sábado","6_sábado",I11="domingo","7_domingo") -> 1_lunes | L11: Divulgación | M11: =COUNTIF(B$2:B$350, "divulgacion") -> 14 | N11: =(COUNTIF(B$2:B4356, "divulgacion")/COUNTA(B$2:B$350)*100) -> 5.3639847 | O11: =AVERAGEIF($B$2:$B$350,$B$28,$D$2:$D$350) -> 25
A12: 45671 | B12: ficcion | C12: español | D12: 14 | E12: si | F12: tarde | G12: enero | H12: =IFS(G12="enero","01_enero",G12="febrero","02_febrero",G12="marzo","03_marzo",G12="abril","04_abril",G12="mayo","05_mayo",G12="junio","06_junio",G12="julio","07_julio",G12="agosto","08_agosto",G12="septiembre","09_septiembre",G12="octubre","10_octubre",G12="noviembre","11_noviembre",G12="diciembre","12_diciembre") -> 01_enero | I12: martes | J12: =IFS(I12="lunes","1_lunes",I12="martes","2_martes",I12="miércoles","3_miércoles",I12="jueves","4_jueves",I12="viernes","5_viernes",I12="sábado","6_sábado",I12="domingo","7_domingo") -> 2_martes | L12: Total: | M12: =SUM(M5:M11) -> 261
A13: 45672 | B13: novela_grafica | C13: español | D13: 18 | E13: si | F13: mañana | G13: enero | H13: =IFS(G13="enero","01_enero",G13="febrero","02_febrero",G13="marzo","03_marzo",G13="abril","04_abril",G13="mayo","05_mayo",G13="junio","06_junio",G13="julio","07_julio",G13="agosto","08_agosto",G13="septiembre","09_septiembre",G13="octubre","10_octubre",G13="noviembre","11_noviembre",G13="diciembre","12_diciembre") -> 01_enero | I13: miércoles | J13: =IFS(I13="lunes","1_lunes",I13="martes","2_martes",I13="miércoles","3_miércoles",I13="jueves","4_jueves",I13="viernes","5_viernes",I13="sábado","6_sábado",I13="domingo","7_domingo") -> 3_miércoles | L13: Máximo días préstamo: | M13: 35 | N13: Promedio préstamos | O13: =AVERAGE(O5:O12) -> 16.841022
A14: 45673 | B14: novela_grafica | C14: español | D14: 20 | E14: si | F14: mañana | G14: enero | H14: =IFS(G14="enero","01_enero",G14="febrero","02_febrero",G14="marzo","03_marzo",G14="abril","04_abril",G14="mayo","05_mayo",G14="junio","06_junio",G14="julio","07_julio",G14="agosto","08_agosto",G14="septiembre","09_septiembre",G14="octubre","10_octubre",G14="noviembre","11_noviembre",G14="diciembre","12_diciembre") -> 01_enero | I14: jueves | J14: =IFS(I14="lunes","1_lunes",I14="martes","2_martes",I14="miércoles","3_miércoles",I14="jueves","4_jueves",I14="viernes","5_viernes",I14="sábado","6_sábado",I14="domingo","7_domingo") -> 4_jueves | L14: Mínimo días préstamo: | M14: 7
A15: 45674 | B15: ensayo | C15: catalán | D15: 25 | E15: si | F15: tarde | G15: enero | H15: =IFS(G15="enero","01_enero",G15="febrero","02_febrero",G15="marzo","03_marzo",G15="abril","04_abril",G15="mayo","05_mayo",G15="junio","06_junio",G15="julio","07_julio",G15="agosto","08_agosto",G15="septiembre","09_septiembre",G15="octubre","10_octubre",G15="noviembre","11_noviembre",G15="diciembre","12_diciembre") -> 01_enero | I15: viernes | J15: =IFS(I15="lunes","1_lunes",I15="martes","2_martes",I15="miércoles","3_miércoles",I15="jueves","4_jueves",I15="viernes","5_viernes",I15="sábado","6_sábado",I15="domingo","7_domingo") -> 5_viernes
A16: 45675 | B16: infantil | C16: catalán | D16: 11 | E16: si | F16: tarde | G16: enero | H16: =IFS(G16="enero","01_enero",G16="febrero","02_febrero",G16="marzo","03_marzo",G16="abril","04_abril",G16="mayo","05_mayo",G16="junio","06_junio",G16="julio","07_julio",G16="agosto","08_agosto",G16="septiembre","09_septiembre",G16="octubre","10_octubre",G16="noviembre","11_noviembre",G16="diciembre","12_diciembre") -> 01_enero | I16: sábado | J16: =IFS(I16="lunes","1_lunes",I16="martes","2_martes",I16="miércoles","3_miércoles",I16="jueves","4_jueves",I16="viernes","5_viernes",I16="sábado","6_sábado",I16="domingo","7_domingo") -> 6_sábado | L16: Ratio de préstamo: | M16: 0.50867052
A17: 45676 | B17: infantil | C17: español | D17: 8 | E17: si | F17: tarde | G17: enero | H17: =IFS(G17="enero","01_enero",G17="febrero","02_febrero",G17="marzo","03_marzo",G17="abril","04_abril",G17="mayo","05_mayo",G17="junio","06_junio",G17="julio","07_julio",G17="agosto","08_agosto",G17="septiembre","09_septiembre",G17="octubre","10_octubre",G17="noviembre","11_noviembre",G17="diciembre","12_diciembre") -> 01_enero | I17: domingo | J17: =IFS(I17="lunes","1_lunes",I17="martes","2_martes",I17="miércoles","3_miércoles",I17="jueves","4_jueves",I17="viernes","5_viernes",I17="sábado","6_sábado",I17="domingo","7_domingo") -> 7_domingo | L17: Préstamos mañana: | M17: 88
A18: 45677 | B18: ficcion | C18: español | D18: 14 | E18: si | F18: tarde | G18: enero | H18: =IFS(G18="enero","01_enero",G18="febrero","02_febrero",G18="marzo","03_marzo",G18="abril","04_abril",G18="mayo","05_mayo",G18="junio","06_junio",G18="julio","07_julio",G18="agosto","08_agosto",G18="septiembre","09_septiembre",G18="octubre","10_octubre",G18="noviembre","11_noviembre",G18="diciembre","12_diciembre") -> 01_enero | I18: lunes | J18: =IFS(I18="lunes","1_lunes",I18="martes","2_martes",I18="miércoles","3_miércoles",I18="jueves","4_jueves",I18="viernes","5_viernes",I18="sábado","6_sábado",I18="domingo","7_domingo") -> 1_lunes | L18: Préstamos tarde: | M18: 173
A19: 45678 | B19: ficcion | C19: español | D19: 14 | E19: si | F19: mañana | G19: enero | H19: =IFS(G19="enero","01_enero",G19="febrero","02_febrero",G19="marzo","03_marzo",G19="abril","04_abril",G19="mayo","05_mayo",G19="junio","06_junio",G19="julio","07_julio",G19="agosto","08_agosto",G19="septiembre","09_septiembre",G19="octubre","10_octubre",G19="noviembre","11_noviembre",G19="diciembre","12_diciembre") -> 01_enero | I19: martes | J19: =IFS(I19="lunes","1_lunes",I19="martes","2_martes",I19="miércoles","3_miércoles",I19="jueves","4_jueves",I19="viernes","5_viernes",I19="sábado","6_sábado",I19="domingo","7_domingo") -> 2_martes
A20: 45679 | B20: poesia | C20: español | D20: 30 | E20: no | F20: tarde | G20: enero | H20: =IFS(G20="enero","01_enero",G20="febrero","02_febrero",G20="marzo","03_marzo",G20="abril","04_abril",G20="mayo","05_mayo",G20="junio","06_junio",G20="julio","07_julio",G20="agosto","08_agosto",G20="septiembre","09_septiembre",G20="octubre","10_octubre",G20="noviembre","11_noviembre",G20="diciembre","12_diciembre") -> 01_enero | I20: miércoles | J20: =IFS(I20="lunes","1_lunes",I20="martes","2_martes",I20="miércoles","3_miércoles",I20="jueves","4_jueves",I20="viernes","5_viernes",I20="sábado","6_sábado",I20="domingo","7_domingo") -> 3_miércoles
A21: 45680 | B21: ensayo | C21: español | D21: 24 | E21: si | F21: mañana | G21: enero | H21: =IFS(G21="enero","01_enero",G21="febrero","02_febrero",G21="marzo","03_marzo",G21="abril","04_abril",G21="mayo","05_mayo",G21="junio","06_junio",G21="julio","07_julio",G21="agosto","08_agosto",G21="septiembre","09_septiembre",G21="octubre","10_octubre",G21="noviembre","11_noviembre",G21="diciembre","12_diciembre") -> 01_enero | I21: jueves | J21: =IFS(I21="lunes","1_lunes",I21="martes","2_martes",I21="miércoles","3_miércoles",I21="jueves","4_jueves",I21="viernes","5_viernes",I21="sábado","6_sábado",I21="domingo","7_domingo") -> 4_jueves | L21: Días de la semana: | M21: Prestamos: | N21: % días:
A22: 45681 | B22: ficcion | C22: inglés | D22: 14 | E22: si | F22: tarde | G22: enero | H22: =IFS(G22="enero","01_enero",G22="febrero","02_febrero",G22="marzo","03_marzo",G22="abril","04_abril",G22="mayo","05_mayo",G22="junio","06_junio",G22="julio","07_julio",G22="agosto","08_agosto",G22="septiembre","09_septiembre",G22="octubre","10_octubre",G22="noviembre","11_noviembre",G22="diciembre","12_diciembre") -> 01_enero | I22: viernes | J22: =IFS(I22="lunes","1_lunes",I22="martes","2_martes",I22="miércoles","3_miércoles",I22="jueves","4_jueves",I22="viernes","5_viernes",I22="sábado","6_sábado",I22="domingo","7_domingo") -> 5_viernes | L22: Lunes | M22: =COUNTIF(I$2:I$350,"lunes") -> 21 | N22: =(COUNTIF(I$2:I$350,"lunes")/COUNTA(I$2:I$350)*100) -> 8.045977
A23: 45682 | B23: comic | C23: español | D23: 7 | E23: si | F23: tarde | G23: enero | H23: =IFS(G23="enero","01_enero",G23="febrero","02_febrero",G23="marzo","03_marzo",G23="abril","04_abril",G23="mayo","05_mayo",G23="junio","06_junio",G23="julio","07_julio",G23="agosto","08_agosto",G23="septiembre","09_septiembre",G23="octubre","10_octubre",G23="noviembre","11_noviembre",G23="diciembre","12_diciembre") -> 01_enero | I23: sábado | J23: =IFS(I23="lunes","1_lunes",I23="martes","2_martes",I23="miércoles","3_miércoles",I23="jueves","4_jueves",I23="viernes","5_viernes",I23="sábado","6_sábado",I23="domingo","7_domingo") -> 6_sábado | L23: Martes | M23: =COUNTIF(I$2:I$350,"martes") -> 52 | N23: =(COUNTIF(I$2:I$350,"martes")/COUNTA(I$2:I$350)*100) -> 19.923372
A24: 45683 | B24: comic | C24: español | D24: 7 | E24: si | F24: mañana | G24: enero | H24: =IFS(G24="enero","01_enero",G24="febrero","02_febrero",G24="marzo","03_marzo",G24="abril","04_abril",G24="mayo","05_mayo",G24="junio","06_junio",G24="julio","07_julio",G24="agosto","08_agosto",G24="septiembre","09_septiembre",G24="octubre","10_octubre",G24="noviembre","11_noviembre",G24="diciembre","12_diciembre") -> 01_enero | I24: domingo | J24: =IFS(I24="lunes","1_lunes",I24="martes","2_martes",I24="miércoles","3_miércoles",I24="jueves","4_jueves",I24="viernes","5_viernes",I24="sábado","6_sábado",I24="domingo","7_domingo") -> 7_domingo | L24: Miercoles | M24: =COUNTIF(I$2:I$350,"miércoles") -> 42 | N24: =(COUNTIF(I$2:I$350,"miércoles")/COUNTA(I$2:I$350)*100) -> 16.091954
A25: 45684 | B25: ficcion | C25: español | D25: 14 | E25: si | F25: tarde | G25: enero | H25: =IFS(G25="enero","01_enero",G25="febrero","02_febrero",G25="marzo","03_marzo",G25="abril","04_abril",G25="mayo","05_mayo",G25="junio","06_junio",G25="julio","07_julio",G25="agosto","08_agosto",G25="septiembre","09_septiembre",G25="octubre","10_octubre",G25="noviembre","11_noviembre",G25="diciembre","12_diciembre") -> 01_enero | I25: lunes | J25: =IFS(I25="lunes","1_lunes",I25="martes","2_martes",I25="miércoles","3_miércoles",I25="jueves","4_jueves",I25="viernes","5_viernes",I25="sábado","6_sábado",I25="domingo","7_domingo") -> 1_lunes | L25: Jueves | M25: =COUNTIF(I$2:I$350,"jueves") -> 30 | N25: =(COUNTIF(I$2:I$350,"jueves")/COUNTA(I$2:I$350)*100) -> 11.494253
A26: 45685 | B26: ficcion | C26: español | D26: 16 | E26: si | F26: tarde | G26: enero | H26: =IFS(G26="enero","01_enero",G26="febrero","02_febrero",G26="marzo","03_marzo",G26="abril","04_abril",G26="mayo","05_mayo",G26="junio","06_junio",G26="julio","07_julio",G26="agosto","08_agosto",G26="septiembre","09_septiembre",G26="octubre","10_octubre",G26="noviembre","11_noviembre",G26="diciembre","12_diciembre") -> 01_enero | I26: martes | J26: =IFS(I26="lunes","1_lunes",I26="martes","2_martes",I26="miércoles","3_miércoles",I26="jueves","4_jueves",I26="viernes","5_viernes",I26="sábado","6_sábado",I26="domingo","7_domingo") -> 2_martes | L26: Viernes | M26: =COUNTIF(I$2:I$350,"viernes") -> 43 | N26: =(COUNTIF(I$2:I$350,"viernes")/COUNTA(I$2:I$350)*100) -> 16.475096
A27: 45686 | B27: infantil | C27: español | D27: 9 | E27: si | F27: tarde | G27: enero | H27: =IFS(G27="enero","01_enero",G27="febrero","02_febrero",G27="marzo","03_marzo",G27="abril","04_abril",G27="mayo","05_mayo",G27="junio","06_junio",G27="julio","07_julio",G27="agosto","08_agosto",G27="septiembre","09_septiembre",G27="octubre","10_octubre",G27="noviembre","11_noviembre",G27="diciembre","12_diciembre") -> 01_enero | I27: miércoles | J27: =IFS(I27="lunes","1_lunes",I27="martes","2_martes",I27="miércoles","3_miércoles",I27="jueves","4_jueves",I27="viernes","5_viernes",I27="sábado","6_sábado",I27="domingo","7_domingo") -> 3_miércoles | L27: Sabado | M27: =COUNTIF(I$2:I$350,"sábado") -> 21 | N27: =(COUNTIF(I$2:I$350,"sábado")/COUNTA(I$2:I$350)*100) -> 8.045977
A28: 45687 | B28: divulgacion | C28: inglés | D28: 27 | E28: no | F28: mañana | G28: enero | H28: =IFS(G28="enero","01_enero",G28="febrero","02_febrero",G28="marzo","03_marzo",G28="abril","04_abril",G28="mayo","05_mayo",G28="junio","06_junio",G28="julio","07_julio",G28="agosto","08_agosto",G28="septiembre","09_septiembre",G28="octubre","10_octubre",G28="noviembre","11_noviembre",G28="diciembre","12_diciembre") -> 01_enero | I28: jueves | J28: =IFS(I28="lunes","1_lunes",I28="martes","2_martes",I28="miércoles","3_miércoles",I28="jueves","4_jueves",I28="viernes","5_viernes",I28="sábado","6_sábado",I28="domingo","7_domingo") -> 4_jueves | L28: Domingo | M28: =COUNTIF(I$2:I$350,"domingo") -> 52 | N28: =(COUNTIF(I$2:I$350,"domingo")/COUNTA(I$2:I$350)*100) -> 19.923372
A29: 45688 | B29: divulgacion | C29: español | D29: 21 | E29: si | F29: mañana | G29: enero | H29: =IFS(G29="enero","01_enero",G29="febrero","02_febrero",G29="marzo","03_marzo",G29="abril","04_abril",G29="mayo","05_mayo",G29="junio","06_junio",G29="julio","07_julio",G29="agosto","08_agosto",G29="septiembre","09_septiembre",G29="octubre","10_octubre",G29="noviembre","11_noviembre",G29="diciembre","12_diciembre") -> 01_enero | I29: viernes | J29: =IFS(I29="lunes","1_lunes",I29="martes","2_martes",I29="miércoles","3_miércoles",I29="jueves","4_jueves",I29="viernes","5_viernes",I29="sábado","6_sábado",I29="domingo","7_domingo") -> 5_viernes
A30: 45689 | B30: infantil | C30: español | D30: 10 | E30: si | F30: tarde | G30: febrero | H30: =IFS(G30="enero","01_enero",G30="febrero","02_febrero",G30="marzo","03_marzo",G30="abril","04_abril",G30="mayo","05_mayo",G30="junio","06_junio",G30="julio","07_julio",G30="agosto","08_agosto",G30="septiembre","09_septiembre",G30="octubre","10_octubre",G30="noviembre","11_noviembre",G30="diciembre","12_diciembre") -> 02_febrero | I30: sábado | J30: =IFS(I30="lunes","1_lunes",I30="martes","2_martes",I30="miércoles","3_miércoles",I30="jueves","4_jueves",I30="viernes","5_viernes",I30="sábado","6_sábado",I30="domingo","7_domingo") -> 6_sábado
A31: 45690 | B31: ficcion | C31: español | D31: 14 | E31: si | F31: tarde | G31: febrero | H31: =IFS(G31="enero","01_enero",G31="febrero","02_febrero",G31="marzo","03_marzo",G31="abril","04_abril",G31="mayo","05_mayo",G31="junio","06_junio",G31="julio","07_julio",G31="agosto","08_agosto",G31="septiembre","09_septiembre",G31="octubre","10_octubre",G31="noviembre","11_noviembre",G31="diciembre","12_diciembre") -> 02_febrero | I31: domingo | J31: =IFS(I31="lunes","1_lunes",I31="martes","2_martes",I31="miércoles","3_miércoles",I31="jueves","4_jueves",I31="viernes","5_viernes",I31="sábado","6_sábado",I31="domingo","7_domingo") -> 7_domingo | L31: Meses | M31: Préstamos mañana | N31: Préstamos tarde | O31: Total préstamos:
A32: 45691 | B32: ficcion | C32: español | D32: 14 | E32: si | F32: tarde | G32: febrero | H32: =IFS(G32="enero","01_enero",G32="febrero","02_febrero",G32="marzo","03_marzo",G32="abril","04_abril",G32="mayo","05_mayo",G32="junio","06_junio",G32="julio","07_julio",G32="agosto","08_agosto",G32="septiembre","09_septiembre",G32="octubre","10_octubre",G32="noviembre","11_noviembre",G32="diciembre","12_diciembre") -> 02_febrero | I32: lunes | J32: =IFS(I32="lunes","1_lunes",I32="martes","2_martes",I32="miércoles","3_miércoles",I32="jueves","4_jueves",I32="viernes","5_viernes",I32="sábado","6_sábado",I32="domingo","7_domingo") -> 1_lunes | L32: Enero | M32: =COUNTIFS($F$2:$F$350, "mañana",$G$2:$G$350,"enero") -> 10 | N32: =COUNTIFS($F$2:$F$350, "tarde",$G$2:$G$350,"enero") -> 18 | O32: =SUM(M32+N32) -> 28
A33: 45692 | B33: infantil | C33: catalán | D33: 12 | E33: si | F33: tarde | G33: febrero | H33: =IFS(G33="enero","01_enero",G33="febrero","02_febrero",G33="marzo","03_marzo",G33="abril","04_abril",G33="mayo","05_mayo",G33="junio","06_junio",G33="julio","07_julio",G33="agosto","08_agosto",G33="septiembre","09_septiembre",G33="octubre","10_octubre",G33="noviembre","11_noviembre",G33="diciembre","12_diciembre") -> 02_febrero | I33: martes | J33: =IFS(I33="lunes","1_lunes",I33="martes","2_martes",I33="miércoles","3_miércoles",I33="jueves","4_jueves",I33="viernes","5_viernes",I33="sábado","6_sábado",I33="domingo","7_domingo") -> 2_martes | L33: Febrero | M33: =COUNTIFS($F$2:$F$350, "mañana",$G$2:$G$350,"febrero") -> 9 | N33: =COUNTIFS($F$2:$F$350, "tarde",$G$2:$G$350,"febrero") -> 19 | O33: =SUM(M33+N33) -> 28
A34: 45693 | B34: ficcion | C34: español | D34: 14 | E34: si | F34: mañana | G34: febrero | H34: =IFS(G34="enero","01_enero",G34="febrero","02_febrero",G34="marzo","03_marzo",G34="abril","04_abril",G34="mayo","05_mayo",G34="junio","06_junio",G34="julio","07_julio",G34="agosto","08_agosto",G34="septiembre","09_septiembre",G34="octubre","10_octubre",G34="noviembre","11_noviembre",G34="diciembre","12_diciembre") -> 02_febrero | I34: miércoles | J34: =IFS(I34="lunes","1_lunes",I34="martes","2_martes",I34="miércoles","3_miércoles",I34="jueves","4_jueves",I34="viernes","5_viernes",I34="sábado","6_sábado",I34="domingo","7_domingo") -> 3_miércoles | L34: Marzo | M34: =COUNTIFS($F$2:$F$350, "mañana",$G$2:$G$350,"marzo") -> 10 | N34: =COUNTIFS($F$2:$F$350, "tarde",$G$2:$G$350,"marzo") -> 21 | O34: =SUM(M34+N34) -> 31
A35: 45694 | B35: ensayo | C35: catalán | D35: 21 | E35: si | F35: mañana | G35: febrero | H35: =IFS(G35="enero","01_enero",G35="febrero","02_febrero",G35="marzo","03_marzo",G35="abril","04_abril",G35="mayo","05_mayo",G35="junio","06_junio",G35="julio","07_julio",G35="agosto","08_agosto",G35="septiembre","09_septiembre",G35="octubre","10_octubre",G35="noviembre","11_noviembre",G35="diciembre","12_diciembre") -> 02_febrero | I35: jueves | J35: =IFS(I35="lunes","1_lunes",I35="martes","2_martes",I35="miércoles","3_miércoles",I35="jueves","4_jueves",I35="viernes","5_viernes",I35="sábado","6_sábado",I35="domingo","7_domingo") -> 4_jueves | L35: Abril | M35: =COUNTIFS($F$2:$F$350, "mañana",$G$2:$G$350,"abril") -> 10 | N35: =COUNTIFS($F$2:$F$350, "tarde",$G$2:$G$350,"abril") -> 20 | O35: =SUM(M35+N35) -> 30
A36: 45695 | B36: ensayo | C36: español | D36: 28 | E36: no | F36: tarde | G36: febrero | H36: =IFS(G36="enero","01_enero",G36="febrero","02_febrero",G36="marzo","03_marzo",G36="abril","04_abril",G36="mayo","05_mayo",G36="junio","06_junio",G36="julio","07_julio",G36="agosto","08_agosto",G36="septiembre","09_septiembre",G36="octubre","10_octubre",G36="noviembre","11_noviembre",G36="diciembre","12_diciembre") -> 02_febrero | I36: viernes | J36: =IFS(I36="lunes","1_lunes",I36="martes","2_martes",I36="miércoles","3_miércoles",I36="jueves","4_jueves",I36="viernes","5_viernes",I36="sábado","6_sábado",I36="domingo","7_domingo") -> 5_viernes | L36: Mayo | M36: =COUNTIFS($F$2:$F$350, "mañana",$G$2:$G$350,"mayo") -> 11 | N36: =COUNTIFS($F$2:$F$350, "tarde",$G$2:$G$350,"mayo") -> 20 | O36: =SUM(M36+N36) -> 31
A37: 45696 | B37: comic | C37: español | D37: 7 | E37: si | F37: tarde | G37: febrero | H37: =IFS(G37="enero","01_enero",G37="febrero","02_febrero",G37="marzo","03_marzo",G37="abril","04_abril",G37="mayo","05_mayo",G37="junio","06_junio",G37="julio","07_julio",G37="agosto","08_agosto",G37="septiembre","09_septiembre",G37="octubre","10_octubre",G37="noviembre","11_noviembre",G37="diciembre","12_diciembre") -> 02_febrero | I37: sábado | J37: =IFS(I37="lunes","1_lunes",I37="martes","2_martes",I37="miércoles","3_miércoles",I37="jueves","4_jueves",I37="viernes","5_viernes",I37="sábado","6_sábado",I37="domingo","7_domingo") -> 6_sábado | L37: Junio | M37: =COUNTIFS($F$2:$F$350, "mañana",$G$2:$G$350,"junio") -> 5 | N37: =COUNTIFS($F$2:$F$350, "tarde",$G$2:$G$350,"junio") -> 12 | O37: =SUM(M37+N37) -> 17
A38: 45697 | B38: comic | C38: español | D38: 7 | E38: si | F38: tarde | G38: febrero | H38: =IFS(G38="enero","01_enero",G38="febrero","02_febrero",G38="marzo","03_marzo",G38="abril","04_abril",G38="mayo","05_mayo",G38="junio","06_junio",G38="julio","07_julio",G38="agosto","08_agosto",G38="septiembre","09_septiembre",G38="octubre","10_octubre",G38="noviembre","11_noviembre",G38="diciembre","12_diciembre") -> 02_febrero | I38: domingo | J38: =IFS(I38="lunes","1_lunes",I38="martes","2_martes",I38="miércoles","3_miércoles",I38="jueves","4_jueves",I38="viernes","5_viernes",I38="sábado","6_sábado",I38="domingo","7_domingo") -> 7_domingo | L38: Julio | M38: =COUNTIFS($F$2:$F$350, "mañana",$G$2:$G$350,"julio") -> 5 | N38: =COUNTIFS($F$2:$F$350, "tarde",$G$2:$G$350,"julio") -> 9 | O38: =SUM(M38+N38) -> 14
A39: 45698 | B39: ficcion | C39: español | D39: 14 | E39: si | F39: tarde | G39: febrero | H39: =IFS(G39="enero","01_enero",G39="febrero","02_febrero",G39="marzo","03_marzo",G39="abril","04_abril",G39="mayo","05_mayo",G39="junio","06_junio",G39="julio","07_julio",G39="agosto","08_agosto",G39="septiembre","09_septiembre",G39="octubre","10_octubre",G39="noviembre","11_noviembre",G39="diciembre","12_diciembre") -> 02_febrero | I39: lunes | J39: =IFS(I39="lunes","1_lunes",I39="martes","2_martes",I39="miércoles","3_miércoles",I39="jueves","4_jueves",I39="viernes","5_viernes",I39="sábado","6_sábado",I39="domingo","7_domingo") -> 1_lunes | L39: Agosto | M39: =COUNTIFS($F$2:$F$350, "mañana",$G$2:$G$350,"agosto") -> 4 | N39: =COUNTIFS($F$2:$F$350, "tarde",$G$2:$G$350,"agosto") -> 9 | O39: =SUM(M39+N39) -> 13
A40: 45699 | B40: ficcion | C40: inglés | D40: 14 | E40: si | F40: mañana | G40: febrero | H40: =IFS(G40="enero","01_enero",G40="febrero","02_febrero",G40="marzo","03_marzo",G40="abril","04_abril",G40="mayo","05_mayo",G40="junio","06_junio",G40="julio","07_julio",G40="agosto","08_agosto",G40="septiembre","09_septiembre",G40="octubre","10_octubre",G40="noviembre","11_noviembre",G40="diciembre","12_diciembre") -> 02_febrero | I40: martes | J40: =IFS(I40="lunes","1_lunes",I40="martes","2_martes",I40="miércoles","3_miércoles",I40="jueves","4_jueves",I40="viernes","5_viernes",I40="sábado","6_sábado",I40="domingo","7_domingo") -> 2_martes | L40: Septiembre | M40: =COUNTIFS($F$2:$F$350, "mañana",$G$2:$G$350,"septiembre") -> 6 | N40: =COUNTIFS($F$2:$F$350, "tarde",$G$2:$G$350,"septiembre") -> 11 | O40: =SUM(M40+N40) -> 17
...

Sheet Copia de Gráficos
B62: MAÑANAS
B63: dia / mes | C63: 01_enero | D63: 02_febrero | E63: 03_marzo | F63: 04_abril | G63: 05_mayo | H63: 06_junio | I63: 07_julio | J63: 08_agosto | K63: 09_septiembre | L63: 10_octubre | M63: 11_noviembre | N63: 12_diciembre
B64: 1_lunes | C64: =COUNTIFS(Tabla!$H$2:$H$262,C$63,Tabla!$J$2:$J$262,$B64,Tabla!$F$2:$F$262,"mañana") -> 0 | D64: =COUNTIFS(Tabla!$H$2:$H$262,D$63,Tabla!$J$2:$J$262,$B64,Tabla!$F$2:$F$262,"mañana") -> 0 | E64: =COUNTIFS(Tabla!$H$2:$H$262,E$63,Tabla!$J$2:$J$262,$B64,Tabla!$F$2:$F$262,"mañana") -> 0 | F64: =COUNTIFS(Tabla!$H$2:$H$262,F$63,Tabla!$J$2:$J$262,$B64,Tabla!$F$2:$F$262,"mañana") -> 0 | G64: =COUNTIFS(Tabla!$H$2:$H$262,G$63,Tabla!$J$2:$J$262,$B64,Tabla!$F$2:$F$262,"mañana") -> 0 | H64: =COUNTIFS(Tabla!$H$2:$H$262,H$63,Tabla!$J$2:$J$262,$B64,Tabla!$F$2:$F$262,"mañana") -> 0 | I64: =COUNTIFS(Tabla!$H$2:$H$262,I$63,Tabla!$J$2:$J$262,$B64,Tabla!$F$2:$F$262,"mañana") -> 0 | J64: =COUNTIFS(Tabla!$H$2:$H$262,J$63,Tabla!$J$2:$J$262,$B64,Tabla!$F$2:$F$262,"mañana") -> 0 | ... N64: =COUNTIFS(Tabla!$H$2:$H$262,N$63,Tabla!$J$2:$J$262,$B64,Tabla!$F$2:$F$262,"mañana") -> 0
B65: 2_martes | C65: =COUNTIFS(Tabla!$H$2:$H$262,C$63,Tabla!$J$2:$J$262,$B65,Tabla!$F$2:$F$262,"mañana") -> 0 | D65: =COUNTIFS(Tabla!$H$2:$H$262,D$63,Tabla!$J$2:$J$262,$B65,Tabla!$F$2:$F$262,"mañana") -> 0 | E65: =COUNTIFS(Tabla!$H$2:$H$262,E$63,Tabla!$J$2:$J$262,$B65,Tabla!$F$2:$F$262,"mañana") -> 0 | F65: =COUNTIFS(Tabla!$H$2:$H$262,F$63,Tabla!$J$2:$J$262,$B65,Tabla!$F$2:$F$262,"mañana") -> 0 | G65: =COUNTIFS(Tabla!$H$2:$H$262,G$63,Tabla!$J$2:$J$262,$B65,Tabla!$F$2:$F$262,"mañana") -> 0 | H65: =COUNTIFS(Tabla!$H$2:$H$262,H$63,Tabla!$J$2:$J$262,$B65,Tabla!$F$2:$F$262,"mañana") -> 0 | I65: =COUNTIFS(Tabla!$H$2:$H$262,I$63,Tabla!$J$2:$J$262,$B65,Tabla!$F$2:$F$262,"mañana") -> 0 | J65: =COUNTIFS(Tabla!$H$2:$H$262,J$63,Tabla!$J$2:$J$262,$B65,Tabla!$F$2:$F$262,"mañana") -> 0 | ... N65: =COUNTIFS(Tabla!$H$2:$H$262,N$63,Tabla!$J$2:$J$262,$B65,Tabla!$F$2:$F$262,"mañana") -> 0
B66: 3_miércoles | C66: =COUNTIFS(Tabla!$H$2:$H$262,C$63,Tabla!$J$2:$J$262,$B66,Tabla!$F$2:$F$262,"mañana") -> 0 | D66: =COUNTIFS(Tabla!$H$2:$H$262,D$63,Tabla!$J$2:$J$262,$B66,Tabla!$F$2:$F$262,"mañana") -> 0 | E66: =COUNTIFS(Tabla!$H$2:$H$262,E$63,Tabla!$J$2:$J$262,$B66,Tabla!$F$2:$F$262,"mañana") -> 0 | F66: =COUNTIFS(Tabla!$H$2:$H$262,F$63,Tabla!$J$2:$J$262,$B66,Tabla!$F$2:$F$262,"mañana") -> 0 | G66: =COUNTIFS(Tabla!$H$2:$H$262,G$63,Tabla!$J$2:$J$262,$B66,Tabla!$F$2:$F$262,"mañana") -> 0 | H66: =COUNTIFS(Tabla!$H$2:$H$262,H$63,Tabla!$J$2:$J$262,$B66,Tabla!$F$2:$F$262,"mañana") -> 0 | I66: =COUNTIFS(Tabla!$H$2:$H$262,I$63,Tabla!$J$2:$J$262,$B66,Tabla!$F$2:$F$262,"mañana") -> 0 | J66: =COUNTIFS(Tabla!$H$2:$H$262,J$63,Tabla!$J$2:$J$262,$B66,Tabla!$F$2:$F$262,"mañana") -> 0 | ... N66: =COUNTIFS(Tabla!$H$2:$H$262,N$63,Tabla!$J$2:$J$262,$B66,Tabla!$F$2:$F$262,"mañana") -> 0
B67: 4_jueves | C67: =COUNTIFS(Tabla!$H$2:$H$262,C$63,Tabla!$J$2:$J$262,$B67,Tabla!$F$2:$F$262,"mañana") -> 0 | D67: =COUNTIFS(Tabla!$H$2:$H$262,D$63,Tabla!$J$2:$J$262,$B67,Tabla!$F$2:$F$262,"mañana") -> 0 | E67: =COUNTIFS(Tabla!$H$2:$H$262,E$63,Tabla!$J$2:$J$262,$B67,Tabla!$F$2:$F$262,"mañana") -> 0 | F67: =COUNTIFS(Tabla!$H$2:$H$262,F$63,Tabla!$J$2:$J$262,$B67,Tabla!$F$2:$F$262,"mañana") -> 0 | G67: =COUNTIFS(Tabla!$H$2:$H$262,G$63,Tabla!$J$2:$J$262,$B67,Tabla!$F$2:$F$262,"mañana") -> 0 | H67: =COUNTIFS(Tabla!$H$2:$H$262,H$63,Tabla!$J$2:$J$262,$B67,Tabla!$F$2:$F$262,"mañana") -> 0 | I67: =COUNTIFS(Tabla!$H$2:$H$262,I$63,Tabla!$J$2:$J$262,$B67,Tabla!$F$2:$F$262,"mañana") -> 0 | J67: =COUNTIFS(Tabla!$H$2:$H$262,J$63,Tabla!$J$2:$J$262,$B67,Tabla!$F$2:$F$262,"mañana") -> 0 | ... N67: =COUNTIFS(Tabla!$H$2:$H$262,N$63,Tabla!$J$2:$J$262,$B67,Tabla!$F$2:$F$262,"mañana") -> 0
B68: 5_viernes | C68: =COUNTIFS(Tabla!$H$2:$H$262,C$63,Tabla!$J$2:$J$262,$B68,Tabla!$F$2:$F$262,"mañana") -> 0 | D68: =COUNTIFS(Tabla!$H$2:$H$262,D$63,Tabla!$J$2:$J$262,$B68,Tabla!$F$2:$F$262,"mañana") -> 0 | E68: =COUNTIFS(Tabla!$H$2:$H$262,E$63,Tabla!$J$2:$J$262,$B68,Tabla!$F$2:$F$262,"mañana") -> 0 | F68: =COUNTIFS(Tabla!$H$2:$H$262,F$63,Tabla!$J$2:$J$262,$B68,Tabla!$F$2:$F$262,"mañana") -> 0 | G68: =COUNTIFS(Tabla!$H$2:$H$262,G$63,Tabla!$J$2:$J$262,$B68,Tabla!$F$2:$F$262,"mañana") -> 0 | H68: =COUNTIFS(Tabla!$H$2:$H$262,H$63,Tabla!$J$2:$J$262,$B68,Tabla!$F$2:$F$262,"mañana") -> 0 | I68: =COUNTIFS(Tabla!$H$2:$H$262,I$63,Tabla!$J$2:$J$262,$B68,Tabla!$F$2:$F$262,"mañana") -> 0 | J68: =COUNTIFS(Tabla!$H$2:$H$262,J$63,Tabla!$J$2:$J$262,$B68,Tabla!$F$2:$F$262,"mañana") -> 0 | ... N68: =COUNTIFS(Tabla!$H$2:$H$262,N$63,Tabla!$J$2:$J$262,$B68,Tabla!$F$2:$F$262,"mañana") -> 0
B69: 6_sábado | C69: =COUNTIFS(Tabla!$H$2:$H$262,C$63,Tabla!$J$2:$J$262,$B69,Tabla!$F$2:$F$262,"mañana") -> 0 | D69: =COUNTIFS(Tabla!$H$2:$H$262,D$63,Tabla!$J$2:$J$262,$B69,Tabla!$F$2:$F$262,"mañana") -> 0 | E69: =COUNTIFS(Tabla!$H$2:$H$262,E$63,Tabla!$J$2:$J$262,$B69,Tabla!$F$2:$F$262,"mañana") -> 0 | F69: =COUNTIFS(Tabla!$H$2:$H$262,F$63,Tabla!$J$2:$J$262,$B69,Tabla!$F$2:$F$262,"mañana") -> 0 | G69: =COUNTIFS(Tabla!$H$2:$H$262,G$63,Tabla!$J$2:$J$262,$B69,Tabla!$F$2:$F$262,"mañana") -> 0 | H69: =COUNTIFS(Tabla!$H$2:$H$262,H$63,Tabla!$J$2:$J$262,$B69,Tabla!$F$2:$F$262,"mañana") -> 0 | I69: =COUNTIFS(Tabla!$H$2:$H$262,I$63,Tabla!$J$2:$J$262,$B69,Tabla!$F$2:$F$262,"mañana") -> 0 | J69: =COUNTIFS(Tabla!$H$2:$H$262,J$63,Tabla!$J$2:$J$262,$B69,Tabla!$F$2:$F$262,"mañana") -> 0 | ... N69: =COUNTIFS(Tabla!$H$2:$H$262,N$63,Tabla!$J$2:$J$262,$B69,Tabla!$F$2:$F$262,"mañana") -> 0
B70: 7_domingo | C70: =COUNTIFS(Tabla!$H$2:$H$262,C$63,Tabla!$J$2:$J$262,$B70,Tabla!$F$2:$F$262,"mañana") -> 0 | D70: =COUNTIFS(Tabla!$H$2:$H$262,D$63,Tabla!$J$2:$J$262,$B70,Tabla!$F$2:$F$262,"mañana") -> 0 | E70: =COUNTIFS(Tabla!$H$2:$H$262,E$63,Tabla!$J$2:$J$262,$B70,Tabla!$F$2:$F$262,"mañana") -> 0 | F70: =COUNTIFS(Tabla!$H$2:$H$262,F$63,Tabla!$J$2:$J$262,$B70,Tabla!$F$2:$F$262,"mañana") -> 0 | G70: =COUNTIFS(Tabla!$H$2:$H$262,G$63,Tabla!$J$2:$J$262,$B70,Tabla!$F$2:$F$262,"mañana") -> 0 | H70: =COUNTIFS(Tabla!$H$2:$H$262,H$63,Tabla!$J$2:$J$262,$B70,Tabla!$F$2:$F$262,"mañana") -> 0 | I70: =COUNTIFS(Tabla!$H$2:$H$262,I$63,Tabla!$J$2:$J$262,$B70,Tabla!$F$2:$F$262,"mañana") -> 0 | J70: =COUNTIFS(Tabla!$H$2:$H$262,J$63,Tabla!$J$2:$J$262,$B70,Tabla!$F$2:$F$262,"mañana") -> 0 | ... N70: =COUNTIFS(Tabla!$H$2:$H$262,N$63,Tabla!$J$2:$J$262,$B70,Tabla!$F$2:$F$262,"mañana") -> 0
B74: TARDES
B75: dia / mes | C75: 01_enero | D75: 02_febrero | E75: 03_marzo | F75: 04_abril | G75: 05_mayo | H75: 06_junio | I75: 07_julio | J75: 08_agosto | K75: 09_septiembre | L75: 10_octubre | M75: 11_noviembre | N75: 12_diciembre
B76: 1_lunes | C76: =COUNTIFS(#REF!,C$63,#REF!,$B76,#REF!,"tarde") -> 0 | D76: =COUNTIFS(#REF!,D$63,#REF!,$B76,#REF!,"tarde") -> 0 | E76: =COUNTIFS(#REF!,E$63,#REF!,$B76,#REF!,"tarde") -> 0 | F76: =COUNTIFS(#REF!,F$63,#REF!,$B76,#REF!,"tarde") -> 0 | G76: =COUNTIFS(#REF!,G$63,#REF!,$B76,#REF!,"tarde") -> 0 | H76: =COUNTIFS(#REF!,H$63,#REF!,$B76,#REF!,"tarde") -> 0 | I76: =COUNTIFS(#REF!,I$63,#REF!,$B76,#REF!,"tarde") -> 0 | J76: =COUNTIFS(#REF!,J$63,#REF!,$B76,#REF!,"tarde") -> 0 | ... N76: =COUNTIFS(#REF!,N$63,#REF!,$B76,#REF!,"tarde") -> 0
B77: 2_martes | C77: =COUNTIFS(#REF!,C$63,#REF!,$B77,#REF!,"tarde") -> 0 | D77: =COUNTIFS(#REF!,D$63,#REF!,$B77,#REF!,"tarde") -> 0 | E77: =COUNTIFS(#REF!,E$63,#REF!,$B77,#REF!,"tarde") -> 0 | F77: =COUNTIFS(#REF!,F$63,#REF!,$B77,#REF!,"tarde") -> 0 | G77: =COUNTIFS(#REF!,G$63,#REF!,$B77,#REF!,"tarde") -> 0 | H77: =COUNTIFS(#REF!,H$63,#REF!,$B77,#REF!,"tarde") -> 0 | I77: =COUNTIFS(#REF!,I$63,#REF!,$B77,#REF!,"tarde") -> 0 | J77: =COUNTIFS(#REF!,J$63,#REF!,$B77,#REF!,"tarde") -> 0 | ... N77: =COUNTIFS(#REF!,N$63,#REF!,$B77,#REF!,"tarde") -> 0
B78: 3_miércoles | C78: =COUNTIFS(#REF!,C$63,#REF!,$B78,#REF!,"tarde") -> 0 | D78: =COUNTIFS(#REF!,D$63,#REF!,$B78,#REF!,"tarde") -> 0 | E78: =COUNTIFS(#REF!,E$63,#REF!,$B78,#REF!,"tarde") -> 0 | F78: =COUNTIFS(#REF!,F$63,#REF!,$B78,#REF!,"tarde") -> 0 | G78: =COUNTIFS(#REF!,G$63,#REF!,$B78,#REF!,"tarde") -> 0 | H78: =COUNTIFS(#REF!,H$63,#REF!,$B78,#REF!,"tarde") -> 0 | I78: =COUNTIFS(#REF!,I$63,#REF!,$B78,#REF!,"tarde") -> 0 | J78: =COUNTIFS(#REF!,J$63,#REF!,$B78,#REF!,"tarde") -> 0 | ... N78: =COUNTIFS(#REF!,N$63,#REF!,$B78,#REF!,"tarde") -> 0
B79: 4_jueves | C79: =COUNTIFS(#REF!,C$63,#REF!,$B79,#REF!,"tarde") -> 0 | D79: =COUNTIFS(#REF!,D$63,#REF!,$B79,#REF!,"tarde") -> 0 | E79: =COUNTIFS(#REF!,E$63,#REF!,$B79,#REF!,"tarde") -> 0 | F79: =COUNTIFS(#REF!,F$63,#REF!,$B79,#REF!,"tarde") -> 0 | G79: =COUNTIFS(#REF!,G$63,#REF!,$B79,#REF!,"tarde") -> 0 | H79: =COUNTIFS(#REF!,H$63,#REF!,$B79,#REF!,"tarde") -> 0 | I79: =COUNTIFS(#REF!,I$63,#REF!,$B79,#REF!,"tarde") -> 0 | J79: =COUNTIFS(#REF!,J$63,#REF!,$B79,#REF!,"tarde") -> 0 | ... N79: =COUNTIFS(#REF!,N$63,#REF!,$B79,#REF!,"tarde") -> 0
B80: 5_viernes | C80: =COUNTIFS(#REF!,C$63,#REF!,$B80,#REF!,"tarde") -> 0 | D80: =COUNTIFS(#REF!,D$63,#REF!,$B80,#REF!,"tarde") -> 0 | E80: =COUNTIFS(#REF!,E$63,#REF!,$B80,#REF!,"tarde") -> 0 | F80: =COUNTIFS(#REF!,F$63,#REF!,$B80,#REF!,"tarde") -> 0 | G80: =COUNTIFS(#REF!,G$63,#REF!,$B80,#REF!,"tarde") -> 0 | H80: =COUNTIFS(#REF!,H$63,#REF!,$B80,#REF!,"tarde") -> 0 | I80: =COUNTIFS(#REF!,I$63,#REF!,$B80,#REF!,"tarde") -> 0 | J80: =COUNTIFS(#REF!,J$63,#REF!,$B80,#REF!,"tarde") -> 0 | ... N80: =COUNTIFS(#REF!,N$63,#REF!,$B80,#REF!,"tarde") -> 0
B81: 6_sábado | C81: =COUNTIFS(#REF!,C$63,#REF!,$B81,#REF!,"tarde") -> 0 | D81: =COUNTIFS(#REF!,D$63,#REF!,$B81,#REF!,"tarde") -> 0 | E81: =COUNTIFS(#REF!,E$63,#REF!,$B81,#REF!,"tarde") -> 0 | F81: =COUNTIFS(#REF!,F$63,#REF!,$B81,#REF!,"tarde") -> 0 | G81: =COUNTIFS(#REF!,G$63,#REF!,$B81,#REF!,"tarde") -> 0 | H81: =COUNTIFS(#REF!,H$63,#REF!,$B81,#REF!,"tarde") -> 0 | I81: =COUNTIFS(#REF!,I$63,#REF!,$B81,#REF!,"tarde") -> 0 | J81: =COUNTIFS(#REF!,J$63,#REF!,$B81,#REF!,"tarde") -> 0 | ... N81: =COUNTIFS(#REF!,N$63,#REF!,$B81,#REF!,"tarde") -> 0
B82: 7_domingo | C82: =COUNTIFS(#REF!,C$63,#REF!,$B82,#REF!,"tarde") -> 0 | D82: =COUNTIFS(#REF!,D$63,#REF!,$B82,#REF!,"tarde") -> 0 | E82: =COUNTIFS(#REF!,E$63,#REF!,$B82,#REF!,"tarde") -> 0 | F82: =COUNTIFS(#REF!,F$63,#REF!,$B82,#REF!,"tarde") -> 0 | G82: =COUNTIFS(#REF!,G$63,#REF!,$B82,#REF!,"tarde") -> 0 | H82: =COUNTIFS(#REF!,H$63,#REF!,$B82,#REF!,"tarde") -> 0 | I82: =COUNTIFS(#REF!,I$63,#REF!,$B82,#REF!,"tarde") -> 0 | J82: =COUNTIFS(#REF!,J$63,#REF!,$B82,#REF!,"tarde") -> 0 | ... N82: =COUNTIFS(#REF!,N$63,#REF!,$B82,#REF!,"tarde") -> 0
C85: lunes por la mañana ningún registro: quizás pueda estar cerrado o nadie puede ir a por libros
C86: martes mañanas solo de julio y agosto
C87: miércoles de marzo y de septiembre solo de mañana; julio y agosto día completo
C90: sábados mañana ningún registro: quizás pueda estar cerrado o quizás nadie puede ir a por libros
